2021-06-21 16:19:24,137 ERROR: Exception on /favicon.ico [GET] [in C:\Users\son_n\.conda\envs\flask\lib\site-packages\flask\app.py: 1891]
Traceback (most recent call last):
  File "C:\Users\son_n\.conda\envs\flask\lib\site-packages\flask\app.py", line 2447, in wsgi_app
    response = self.full_dispatch_request()
  File "C:\Users\son_n\.conda\envs\flask\lib\site-packages\flask\app.py", line 1952, in full_dispatch_request
    rv = self.handle_user_exception(e)
  File "C:\Users\son_n\.conda\envs\flask\lib\site-packages\flask\app.py", line 1821, in handle_user_exception
    reraise(exc_type, exc_value, tb)
  File "C:\Users\son_n\.conda\envs\flask\lib\site-packages\flask\_compat.py", line 39, in reraise
    raise value
  File "C:\Users\son_n\.conda\envs\flask\lib\site-packages\flask\app.py", line 1950, in full_dispatch_request
    rv = self.dispatch_request()
  File "C:\Users\son_n\.conda\envs\flask\lib\site-packages\flask\app.py", line 1936, in dispatch_request
    return self.view_functions[rule.endpoint](**req.view_args)
  File "d:\software_laptrinh\Python Learning\10. Tu_vi\app\routes.py", line 79, in truy_xuat_gia_chu
    thong_tin_gia_chu = chuoi_HTML_gia_chu(gia_chu_username)
  File "d:\software_laptrinh\Python Learning\10. Tu_vi\app\routes.py", line 156, in chuoi_HTML_gia_chu
    can, chi = thong_tin.can_chi.split(' ')
AttributeError: 'NoneType' object has no attribute 'can_chi'
2021-06-21 16:19:27,272 ERROR: Exception on /favicon.ico [GET] [in C:\Users\son_n\.conda\envs\flask\lib\site-packages\flask\app.py: 1891]
Traceback (most recent call last):
  File "C:\Users\son_n\.conda\envs\flask\lib\site-packages\flask\app.py", line 2447, in wsgi_app
    response = self.full_dispatch_request()
  File "C:\Users\son_n\.conda\envs\flask\lib\site-packages\flask\app.py", line 1952, in full_dispatch_request
    rv = self.handle_user_exception(e)
  File "C:\Users\son_n\.conda\envs\flask\lib\site-packages\flask\app.py", line 1821, in handle_user_exception
    reraise(exc_type, exc_value, tb)
  File "C:\Users\son_n\.conda\envs\flask\lib\site-packages\flask\_compat.py", line 39, in reraise
    raise value
  File "C:\Users\son_n\.conda\envs\flask\lib\site-packages\flask\app.py", line 1950, in full_dispatch_request
    rv = self.dispatch_request()
  File "C:\Users\son_n\.conda\envs\flask\lib\site-packages\flask\app.py", line 1936, in dispatch_request
    return self.view_functions[rule.endpoint](**req.view_args)
  File "d:\software_laptrinh\Python Learning\10. Tu_vi\app\routes.py", line 79, in truy_xuat_gia_chu
    thong_tin_gia_chu = chuoi_HTML_gia_chu(gia_chu_username)
  File "d:\software_laptrinh\Python Learning\10. Tu_vi\app\routes.py", line 156, in chuoi_HTML_gia_chu
    can, chi = thong_tin.can_chi.split(' ')
AttributeError: 'NoneType' object has no attribute 'can_chi'
2021-06-21 16:19:58,012 ERROR: Exception on /favicon.ico [GET] [in C:\Users\son_n\.conda\envs\flask\lib\site-packages\flask\app.py: 1891]
Traceback (most recent call last):
  File "C:\Users\son_n\.conda\envs\flask\lib\site-packages\flask\app.py", line 2447, in wsgi_app
    response = self.full_dispatch_request()
  File "C:\Users\son_n\.conda\envs\flask\lib\site-packages\flask\app.py", line 1952, in full_dispatch_request
    rv = self.handle_user_exception(e)
  File "C:\Users\son_n\.conda\envs\flask\lib\site-packages\flask\app.py", line 1821, in handle_user_exception
    reraise(exc_type, exc_value, tb)
  File "C:\Users\son_n\.conda\envs\flask\lib\site-packages\flask\_compat.py", line 39, in reraise
    raise value
  File "C:\Users\son_n\.conda\envs\flask\lib\site-packages\flask\app.py", line 1950, in full_dispatch_request
    rv = self.dispatch_request()
  File "C:\Users\son_n\.conda\envs\flask\lib\site-packages\flask\app.py", line 1936, in dispatch_request
    return self.view_functions[rule.endpoint](**req.view_args)
  File "d:\software_laptrinh\Python Learning\10. Tu_vi\app\routes.py", line 79, in truy_xuat_gia_chu
    thong_tin_gia_chu = chuoi_HTML_gia_chu(gia_chu_username)
  File "d:\software_laptrinh\Python Learning\10. Tu_vi\app\routes.py", line 156, in chuoi_HTML_gia_chu
    can, chi = thong_tin.can_chi.split(' ')
AttributeError: 'NoneType' object has no attribute 'can_chi'
2021-06-21 16:20:00,762 ERROR: Exception on /favicon.ico [GET] [in C:\Users\son_n\.conda\envs\flask\lib\site-packages\flask\app.py: 1891]
Traceback (most recent call last):
  File "C:\Users\son_n\.conda\envs\flask\lib\site-packages\flask\app.py", line 2447, in wsgi_app
    response = self.full_dispatch_request()
  File "C:\Users\son_n\.conda\envs\flask\lib\site-packages\flask\app.py", line 1952, in full_dispatch_request
    rv = self.handle_user_exception(e)
  File "C:\Users\son_n\.conda\envs\flask\lib\site-packages\flask\app.py", line 1821, in handle_user_exception
    reraise(exc_type, exc_value, tb)
  File "C:\Users\son_n\.conda\envs\flask\lib\site-packages\flask\_compat.py", line 39, in reraise
    raise value
  File "C:\Users\son_n\.conda\envs\flask\lib\site-packages\flask\app.py", line 1950, in full_dispatch_request
    rv = self.dispatch_request()
  File "C:\Users\son_n\.conda\envs\flask\lib\site-packages\flask\app.py", line 1936, in dispatch_request
    return self.view_functions[rule.endpoint](**req.view_args)
  File "d:\software_laptrinh\Python Learning\10. Tu_vi\app\routes.py", line 79, in truy_xuat_gia_chu
    thong_tin_gia_chu = chuoi_HTML_gia_chu(gia_chu_username)
  File "d:\software_laptrinh\Python Learning\10. Tu_vi\app\routes.py", line 156, in chuoi_HTML_gia_chu
    can, chi = thong_tin.can_chi.split(' ')
AttributeError: 'NoneType' object has no attribute 'can_chi'
2021-06-21 16:20:14,747 ERROR: Exception on /favicon.ico [GET] [in C:\Users\son_n\.conda\envs\flask\lib\site-packages\flask\app.py: 1891]
Traceback (most recent call last):
  File "C:\Users\son_n\.conda\envs\flask\lib\site-packages\flask\app.py", line 2447, in wsgi_app
    response = self.full_dispatch_request()
  File "C:\Users\son_n\.conda\envs\flask\lib\site-packages\flask\app.py", line 1952, in full_dispatch_request
    rv = self.handle_user_exception(e)
  File "C:\Users\son_n\.conda\envs\flask\lib\site-packages\flask\app.py", line 1821, in handle_user_exception
    reraise(exc_type, exc_value, tb)
  File "C:\Users\son_n\.conda\envs\flask\lib\site-packages\flask\_compat.py", line 39, in reraise
    raise value
  File "C:\Users\son_n\.conda\envs\flask\lib\site-packages\flask\app.py", line 1950, in full_dispatch_request
    rv = self.dispatch_request()
  File "C:\Users\son_n\.conda\envs\flask\lib\site-packages\flask\app.py", line 1936, in dispatch_request
    return self.view_functions[rule.endpoint](**req.view_args)
  File "d:\software_laptrinh\Python Learning\10. Tu_vi\app\routes.py", line 79, in truy_xuat_gia_chu
    thong_tin_gia_chu = chuoi_HTML_gia_chu(gia_chu_username)
  File "d:\software_laptrinh\Python Learning\10. Tu_vi\app\routes.py", line 156, in chuoi_HTML_gia_chu
    can, chi = thong_tin.can_chi.split(' ')
AttributeError: 'NoneType' object has no attribute 'can_chi'
2021-06-21 16:22:22,912 ERROR: Exception on /favicon.ico [GET] [in C:\Users\son_n\.conda\envs\flask\lib\site-packages\flask\app.py: 1891]
Traceback (most recent call last):
  File "C:\Users\son_n\.conda\envs\flask\lib\site-packages\flask\app.py", line 2447, in wsgi_app
    response = self.full_dispatch_request()
  File "C:\Users\son_n\.conda\envs\flask\lib\site-packages\flask\app.py", line 1952, in full_dispatch_request
    rv = self.handle_user_exception(e)
  File "C:\Users\son_n\.conda\envs\flask\lib\site-packages\flask\app.py", line 1821, in handle_user_exception
    reraise(exc_type, exc_value, tb)
  File "C:\Users\son_n\.conda\envs\flask\lib\site-packages\flask\_compat.py", line 39, in reraise
    raise value
  File "C:\Users\son_n\.conda\envs\flask\lib\site-packages\flask\app.py", line 1950, in full_dispatch_request
    rv = self.dispatch_request()
  File "C:\Users\son_n\.conda\envs\flask\lib\site-packages\flask\app.py", line 1936, in dispatch_request
    return self.view_functions[rule.endpoint](**req.view_args)
  File "d:\software_laptrinh\Python Learning\10. Tu_vi\app\routes.py", line 79, in truy_xuat_gia_chu
    thong_tin_gia_chu = chuoi_HTML_gia_chu(gia_chu_username)
  File "d:\software_laptrinh\Python Learning\10. Tu_vi\app\routes.py", line 156, in chuoi_HTML_gia_chu
    can, chi = thong_tin.can_chi.split(' ')
AttributeError: 'NoneType' object has no attribute 'can_chi'
2021-06-21 16:23:13,555 ERROR: Exception on /favicon.ico [GET] [in C:\Users\son_n\.conda\envs\flask\lib\site-packages\flask\app.py: 1891]
Traceback (most recent call last):
  File "C:\Users\son_n\.conda\envs\flask\lib\site-packages\flask\app.py", line 2447, in wsgi_app
    response = self.full_dispatch_request()
  File "C:\Users\son_n\.conda\envs\flask\lib\site-packages\flask\app.py", line 1952, in full_dispatch_request
    rv = self.handle_user_exception(e)
  File "C:\Users\son_n\.conda\envs\flask\lib\site-packages\flask\app.py", line 1821, in handle_user_exception
    reraise(exc_type, exc_value, tb)
  File "C:\Users\son_n\.conda\envs\flask\lib\site-packages\flask\_compat.py", line 39, in reraise
    raise value
  File "C:\Users\son_n\.conda\envs\flask\lib\site-packages\flask\app.py", line 1950, in full_dispatch_request
    rv = self.dispatch_request()
  File "C:\Users\son_n\.conda\envs\flask\lib\site-packages\flask\app.py", line 1936, in dispatch_request
    return self.view_functions[rule.endpoint](**req.view_args)
  File "d:\software_laptrinh\Python Learning\10. Tu_vi\app\routes.py", line 79, in truy_xuat_gia_chu
    thong_tin_gia_chu = chuoi_HTML_gia_chu(gia_chu_username)
  File "d:\software_laptrinh\Python Learning\10. Tu_vi\app\routes.py", line 156, in chuoi_HTML_gia_chu
    can, chi = thong_tin.can_chi.split(' ')
AttributeError: 'NoneType' object has no attribute 'can_chi'
